<?xml version="1.0" encoding="utf-8"?>

<robot xmlns:xacro="http://www.ros.org/wiki/xacro">
  <xacro:macro name="panda" params="name_prefix:='' panda_package_prefix:='package://robot_description/urdf/panda'">

    <link name="${name_prefix}panda_link0">
      <visual>
        <geometry>
          <mesh filename="${panda_package_prefix}/meshes/visual/link0.dae"/>
        </geometry>
      </visual>
      <collision>
        <geometry>
          <mesh filename="${panda_package_prefix}/meshes/collision/link0.stl"/>
        </geometry>
      </collision>
      <inertial>
        <origin xyz="-0.0172 0.0004 0.0745" rpy="0 0 0"/>
        <mass value="2.3966"/>
        <inertia ixx="0.0090" ixy="0.0000" ixz="0.0020" iyy="0.0115" iyz="0.0000" izz="0.0085"/>
      </inertial>
    </link>
    <link name="${name_prefix}panda_link1">
      <visual>
        <geometry>
          <mesh filename="${panda_package_prefix}/meshes/visual/link1.dae"/>
        </geometry>
      </visual>
      <collision>
        <geometry>
          <mesh filename="${panda_package_prefix}/meshes/collision/link1.stl"/>
        </geometry>
      </collision>
      <inertial>
        <origin xyz="0.00033 -0.02204 -0.04762" rpy="0 0 0"/>
        <mass value="2.7907"/>
        <inertia ixx="0.01564782655" ixy="0.00000531236" ixz="-0.00003676721"
                iyy="0.01439883526" iyz="-0.00248480843" izz="0.00500443991"/>
      </inertial>
    </link>
    <joint name="${name_prefix}panda_joint1" type="revolute">
      <safety_controller k_position="100.0" k_velocity="40.0" soft_lower_limit="-2.8973" soft_upper_limit="2.8973"/>
      <origin rpy="0 0 0" xyz="0 0 0.333"/>
      <parent link="${name_prefix}panda_link0"/>
      <child link="${name_prefix}panda_link1"/>
      <axis xyz="0 0 1"/>
      <limit effort="87" lower="-2.8973" upper="2.8973" velocity="2.1750"/>
    </joint>
    <link name="${name_prefix}panda_link2">
      <visual>
        <geometry>
          <mesh filename="${panda_package_prefix}/meshes/visual/link2.dae"/>
        </geometry>
      </visual>
      <collision>
        <geometry>
          <mesh filename="${panda_package_prefix}/meshes/collision/link2.stl"/>
        </geometry>
      </collision>
      <inertial>
        <origin xyz="0.00038 -0.09211 0.01908" rpy="0 0 0"/>
        <mass value="2.5420"/>
        <inertia ixx="0.01662427728" ixy="0.00003086077" ixz="0.00000835940"
                iyy="0.00462501261" iyz="0.00355899830" izz="0.01545124526"/>
      </inertial>
    </link>
    <joint name="${name_prefix}panda_joint2" type="revolute">
      <safety_controller k_position="100.0" k_velocity="40.0" soft_lower_limit="-1.7628" soft_upper_limit="1.7628"/>
      <origin rpy="-1.57079632679 0 0" xyz="0 0 0"/>
      <parent link="${name_prefix}panda_link1"/>
      <child link="${name_prefix}panda_link2"/>
      <axis xyz="0 0 1"/>
      <limit effort="87" lower="-1.7628" upper="1.7628" velocity="2.1750"/>
    </joint>
    <link name="${name_prefix}panda_link3">
      <visual>
        <geometry>
          <mesh filename="${panda_package_prefix}/meshes/visual/link3.dae"/>
        </geometry>
      </visual>
      <collision>
        <geometry>
          <mesh filename="${panda_package_prefix}/meshes/collision/link3.stl"/>
        </geometry>
      </collision>
      <inertial>
        <origin xyz="0.05152 0.01696 -0.02971" rpy="0 0 0"/>
        <mass value="2.2513"/>
        <inertia ixx="0.00631741992" ixy="0.00097309955" ixz="0.00292525834"
                iyy="0.00866285493" iyz="0.00093469224" izz="0.00657804051"/>
      </inertial>
    </link>
    <joint name="${name_prefix}panda_joint3" type="revolute">
      <safety_controller k_position="100.0" k_velocity="40.0" soft_lower_limit="-2.8973" soft_upper_limit="2.8973"/>
      <origin rpy="1.57079632679 0 0" xyz="0 -0.316 0"/>
      <parent link="${name_prefix}panda_link2"/>
      <child link="${name_prefix}panda_link3"/>
      <axis xyz="0 0 1"/>
      <limit effort="87" lower="-2.8973" upper="2.8973" velocity="2.1750"/>
    </joint>
    <link name="${name_prefix}panda_link4">
      <visual>
        <geometry>
          <mesh filename="${panda_package_prefix}/meshes/visual/link4.dae"/>
        </geometry>
      </visual>
      <collision>
        <geometry>
          <mesh filename="${panda_package_prefix}/meshes/collision/link4.stl"/>
        </geometry>
      </collision>
      <inertial>
        <origin xyz="-0.05113 0.05825 0.01698" rpy="0 0 0"/>
        <mass value="2.2037"/>
        <inertia ixx="0.00784585566" ixy="-0.00339591957" ixz="0.00158704074"
                iyy="0.00649543136" iyz="-0.00181477884" izz="0.01003079917"/>
      </inertial>
    </link>
    <joint name="${name_prefix}panda_joint4" type="revolute">
      <safety_controller k_position="100.0" k_velocity="40.0" soft_lower_limit="-3.0718" soft_upper_limit="-0.0698"/>
      <origin rpy="1.57079632679 0 0" xyz="0.0825 0 0"/>
      <parent link="${name_prefix}panda_link3"/>
      <child link="${name_prefix}panda_link4"/>
      <axis xyz="0 0 1"/>
      <limit effort="87" lower="-3.0718" upper="-0.0698" velocity="2.1750"/>
    </joint>
    <link name="${name_prefix}panda_link5">
      <visual>
        <geometry>
          <mesh filename="${panda_package_prefix}/meshes/visual/link5.dae"/>
        </geometry>
      </visual>
      <collision>
        <geometry>
          <mesh filename="${panda_package_prefix}/meshes/collision/link5.stl"/>
        </geometry>
      </collision>
      <inertial>
        <origin xyz="-0.00005 0.03730 -0.09280" rpy="0 0 0"/>
        <mass value="2.2855"/>
        <inertia ixx="0.02297014781" ixy="-0.00000949345" ixz="-0.00002063156"
                iyy="0.02095060919" iyz="0.00382345782" izz="0.00430606551"/>
      </inertial>
    </link>
    <joint name="${name_prefix}panda_joint5" type="revolute">
      <safety_controller k_position="100.0" k_velocity="40.0" soft_lower_limit="-2.8973" soft_upper_limit="2.8973"/>
      <origin rpy="-1.57079632679 0 0" xyz="-0.0825 0.384 0"/>
      <parent link="${name_prefix}panda_link4"/>
      <child link="${name_prefix}panda_link5"/>
      <axis xyz="0 0 1"/>
      <limit effort="12" lower="-2.8973" upper="2.8973" velocity="2.6100"/>
    </joint>
    <link name="${name_prefix}panda_link6">
      <visual>
        <geometry>
          <mesh filename="${panda_package_prefix}/meshes/visual/link6.dae"/>
        </geometry>
      </visual>
      <collision>
        <geometry>
          <mesh filename="${panda_package_prefix}/meshes/collision/link6.stl"/>
        </geometry>
      </collision>
      <inertial>
        <origin xyz="0.06572 -0.00371 0.00153" rpy="0 0 0"/>
        <mass value="1.353"/>
        <inertia ixx="0.00087964522" ixy="-0.00021487814" ixz="-0.00011911662"
                iyy="0.00277796968" iyz="0.00001274322" izz="0.00286701969"/>
      </inertial>
    </link>
    <joint name="${name_prefix}panda_joint6" type="revolute">
      <safety_controller k_position="100.0" k_velocity="40.0" soft_lower_limit="-0.0175" soft_upper_limit="3.7525"/>
      <origin rpy="1.57079632679 0 0" xyz="0 0 0"/>
      <parent link="${name_prefix}panda_link5"/>
      <child link="${name_prefix}panda_link6"/>
      <axis xyz="0 0 1"/>
      <limit effort="12" lower="-0.0175" upper="3.7525" velocity="2.6100"/>
    </joint>
    <link name="${name_prefix}panda_link7">
      <visual>
        <geometry>
          <mesh filename="${panda_package_prefix}/meshes/visual/link7.dae"/>
        </geometry>
      </visual>
      <collision>
        <geometry>
          <mesh filename="${panda_package_prefix}/meshes/collision/link7.stl"/>
        </geometry>
      </collision>
      <inertial>
        <origin xyz="0.00089 -0.00044 0.05491" rpy="0 0 0"/>
        <mass value="0.35973"/>
        <inertia ixx="0.00019541063" ixy="0.00000165231" ixz="0.00000148826"
                iyy="0.00019210361" iyz="-0.00000131132" izz="0.00017936256"/>
      </inertial>
    </link>
    <joint name="${name_prefix}panda_joint7" type="revolute">
      <safety_controller k_position="100.0" k_velocity="40.0" soft_lower_limit="-2.8973" soft_upper_limit="2.8973"/>
      <origin rpy="1.57079632679 0 0" xyz="0.088 0 0"/>
      <parent link="${name_prefix}panda_link6"/>
      <child link="${name_prefix}panda_link7"/>
      <axis xyz="0 0 1"/>
      <limit effort="12" lower="-2.8973" upper="2.8973" velocity="2.6100"/>
    </joint>
    <link name="${name_prefix}panda_link8"/>
    <joint name="${name_prefix}panda_joint8" type="fixed">
      <parent link="${name_prefix}panda_link7"/>
      <child link="${name_prefix}panda_link8"/>
      <origin rpy="0 0 0" xyz="0 0 0.107"/>
    </joint>
  </xacro:macro>

</robot>

