<?xml version="1.0" encoding="utf-8"?>

<robot xmlns:xacro="http://www.ros.org/wiki/xacro">
  <xacro:arg name="name_prefix" default=""/>
  <xacro:macro name="panda_hand" params="file_prefix:='package://robot_description/panda' name_prefix:=''">


    <link name="${name_prefix}panda_hand">
      <visual>
        <geometry>
          <mesh filename="${file_prefix}/meshes/visual/hand.dae"/>
        </geometry>
      </visual>
      <collision>
        <geometry>
          <mesh filename="${file_prefix}/meshes/collision/hand.stl"/>
        </geometry>
      </collision>
      <inertial>
        <origin xyz="-0.0000376 0.0119128 0.0207260" rpy="0 0 0"/>
        <mass value="0.6544"/>
        <inertia ixx="0.00186" ixy="0.00000" ixz="0.00000"
                 iyy="0.00030" iyz="-0.00002" izz="0.00174"/>
      </inertial>
    </link>
    <link name="${name_prefix}panda_leftfinger">
      <visual>
        <geometry>
          <mesh filename="${file_prefix}/meshes/visual/finger.dae"/>
        </geometry>
      </visual>
      <collision>
        <geometry>
          <mesh filename="${file_prefix}/meshes/collision/finger.stl"/>
        </geometry>
      </collision>
      <inertial>
        <origin xyz="0 0.0152850 0.0219675" rpy="0 0 0"/>
        <mass value="0.0291"/>
        <inertia ixx="0.00000849" ixy="0.00000000" ixz="0.00000000"
                 iyy="0.00000853" iyz="-0.00000106" izz="0.00000177"/>
      </inertial>
    </link>
    <link name="${name_prefix}panda_rightfinger">
      <visual>
        <origin rpy="0 0 3.14159265359" xyz="0 0 0"/>
        <geometry>
          <mesh filename="${file_prefix}/meshes/visual/finger.dae"/>
        </geometry>
      </visual>
      <collision>
        <origin rpy="0 0 3.14159265359" xyz="0 0 0"/>
        <geometry>
          <mesh filename="${file_prefix}/meshes/collision/finger.stl"/>
        </geometry>
      </collision>
      <inertial>
        <origin xyz="0 0.0152850 0.0219675" rpy="0 0 0"/>
        <mass value="0.0291"/>
        <inertia ixx="0.00000849" ixy="0.00000000" ixz="0.00000000"
                 iyy="0.00000853" iyz="-0.00000106" izz="0.00000177"/>
      </inertial>
    </link>
    <joint name="${name_prefix}panda_finger_joint1" type="prismatic">
      <parent link="${name_prefix}panda_hand"/>
      <child link="${name_prefix}panda_leftfinger"/>
      <origin rpy="0 0 0" xyz="0 0 0.0584"/>
      <axis xyz="0 1 0"/>
      <limit effort="20" lower="0.0" upper="0.04" velocity="0.2"/>
    </joint>
    <joint name="${name_prefix}panda_finger_joint2" type="prismatic">
      <parent link="${name_prefix}panda_hand"/>
      <child link="${name_prefix}panda_rightfinger"/>
      <origin rpy="0 0 0" xyz="0 0 0.0584"/>
      <axis xyz="0 -1 0"/>
      <limit effort="20" lower="0.0" upper="0.04" velocity="0.2"/>
      <mimic joint="${name_prefix}panda_finger_joint1"/>
    </joint>
  </xacro:macro>
</robot>

