<?xml version="1.0" ?>
<!-- =================================================================================== -->
<!-- |    This document was autogenerated by xacro from /workspace/libs/robot_description/ros/src/robot_description/urdf/composites/bimanual_arms.urdf.xacro | -->
<!-- |    EDITING THIS FILE BY HAND IS NOT RECOMMENDED                                 | -->
<!-- =================================================================================== -->
<robot name="bimanual_arms">
  <link name="left_panda_link0">
    <visual>
      <geometry>
        <mesh filename="package://robot_description/urdf/panda/meshes/visual/link0.dae"/>
      </geometry>
    </visual>
    <collision>
      <geometry>
        <mesh filename="package://robot_description/urdf/panda/meshes/collision/link0.stl"/>
      </geometry>
    </collision>
    <inertial>
      <origin rpy="0 0 0" xyz="-0.0172 0.0004 0.0745"/>
      <mass value="2.3966"/>
      <inertia ixx="0.0090" ixy="0.0000" ixz="0.0020" iyy="0.0115" iyz="0.0000" izz="0.0085"/>
    </inertial>
  </link>
  <link name="left_panda_link1">
    <visual>
      <geometry>
        <mesh filename="package://robot_description/urdf/panda/meshes/visual/link1.dae"/>
      </geometry>
    </visual>
    <collision>
      <geometry>
        <mesh filename="package://robot_description/urdf/panda/meshes/collision/link1.stl"/>
      </geometry>
    </collision>
    <inertial>
      <origin rpy="0 0 0" xyz="0.00033 -0.02204 -0.04762"/>
      <mass value="2.7907"/>
      <inertia ixx="0.01564782655" ixy="0.00000531236" ixz="-0.00003676721" iyy="0.01439883526" iyz="-0.00248480843" izz="0.00500443991"/>
    </inertial>
  </link>
  <joint name="left_panda_joint1" type="revolute">
    <safety_controller k_position="100.0" k_velocity="40.0" soft_lower_limit="-2.8973" soft_upper_limit="2.8973"/>
    <origin rpy="0 0 0" xyz="0 0 0.333"/>
    <parent link="left_panda_link0"/>
    <child link="left_panda_link1"/>
    <axis xyz="0 0 1"/>
    <limit effort="87" lower="-2.8973" upper="2.8973" velocity="2.1750"/>
  </joint>
  <link name="left_panda_link2">
    <visual>
      <geometry>
        <mesh filename="package://robot_description/urdf/panda/meshes/visual/link2.dae"/>
      </geometry>
    </visual>
    <collision>
      <geometry>
        <mesh filename="package://robot_description/urdf/panda/meshes/collision/link2.stl"/>
      </geometry>
    </collision>
    <inertial>
      <origin rpy="0 0 0" xyz="0.00038 -0.09211 0.01908"/>
      <mass value="2.5420"/>
      <inertia ixx="0.01662427728" ixy="0.00003086077" ixz="0.00000835940" iyy="0.00462501261" iyz="0.00355899830" izz="0.01545124526"/>
    </inertial>
  </link>
  <joint name="left_panda_joint2" type="revolute">
    <safety_controller k_position="100.0" k_velocity="40.0" soft_lower_limit="-1.7628" soft_upper_limit="1.7628"/>
    <origin rpy="-1.57079632679 0 0" xyz="0 0 0"/>
    <parent link="left_panda_link1"/>
    <child link="left_panda_link2"/>
    <axis xyz="0 0 1"/>
    <limit effort="87" lower="-1.7628" upper="1.7628" velocity="2.1750"/>
  </joint>
  <link name="left_panda_link3">
    <visual>
      <geometry>
        <mesh filename="package://robot_description/urdf/panda/meshes/visual/link3.dae"/>
      </geometry>
    </visual>
    <collision>
      <geometry>
        <mesh filename="package://robot_description/urdf/panda/meshes/collision/link3.stl"/>
      </geometry>
    </collision>
    <inertial>
      <origin rpy="0 0 0" xyz="0.05152 0.01696 -0.02971"/>
      <mass value="2.2513"/>
      <inertia ixx="0.00631741992" ixy="0.00097309955" ixz="0.00292525834" iyy="0.00866285493" iyz="0.00093469224" izz="0.00657804051"/>
    </inertial>
  </link>
  <joint name="left_panda_joint3" type="revolute">
    <safety_controller k_position="100.0" k_velocity="40.0" soft_lower_limit="-2.8973" soft_upper_limit="2.8973"/>
    <origin rpy="1.57079632679 0 0" xyz="0 -0.316 0"/>
    <parent link="left_panda_link2"/>
    <child link="left_panda_link3"/>
    <axis xyz="0 0 1"/>
    <limit effort="87" lower="-2.8973" upper="2.8973" velocity="2.1750"/>
  </joint>
  <link name="left_panda_link4">
    <visual>
      <geometry>
        <mesh filename="package://robot_description/urdf/panda/meshes/visual/link4.dae"/>
      </geometry>
    </visual>
    <collision>
      <geometry>
        <mesh filename="package://robot_description/urdf/panda/meshes/collision/link4.stl"/>
      </geometry>
    </collision>
    <inertial>
      <origin rpy="0 0 0" xyz="-0.05113 0.05825 0.01698"/>
      <mass value="2.2037"/>
      <inertia ixx="0.00784585566" ixy="-0.00339591957" ixz="0.00158704074" iyy="0.00649543136" iyz="-0.00181477884" izz="0.01003079917"/>
    </inertial>
  </link>
  <joint name="left_panda_joint4" type="revolute">
    <safety_controller k_position="100.0" k_velocity="40.0" soft_lower_limit="-3.0718" soft_upper_limit="-0.0698"/>
    <origin rpy="1.57079632679 0 0" xyz="0.0825 0 0"/>
    <parent link="left_panda_link3"/>
    <child link="left_panda_link4"/>
    <axis xyz="0 0 1"/>
    <limit effort="87" lower="-3.0718" upper="-0.0698" velocity="2.1750"/>
  </joint>
  <link name="left_panda_link5">
    <visual>
      <geometry>
        <mesh filename="package://robot_description/urdf/panda/meshes/visual/link5.dae"/>
      </geometry>
    </visual>
    <collision>
      <geometry>
        <mesh filename="package://robot_description/urdf/panda/meshes/collision/link5.stl"/>
      </geometry>
    </collision>
    <inertial>
      <origin rpy="0 0 0" xyz="-0.00005 0.03730 -0.09280"/>
      <mass value="2.2855"/>
      <inertia ixx="0.02297014781" ixy="-0.00000949345" ixz="-0.00002063156" iyy="0.02095060919" iyz="0.00382345782" izz="0.00430606551"/>
    </inertial>
  </link>
  <joint name="left_panda_joint5" type="revolute">
    <safety_controller k_position="100.0" k_velocity="40.0" soft_lower_limit="-2.8973" soft_upper_limit="2.8973"/>
    <origin rpy="-1.57079632679 0 0" xyz="-0.0825 0.384 0"/>
    <parent link="left_panda_link4"/>
    <child link="left_panda_link5"/>
    <axis xyz="0 0 1"/>
    <limit effort="12" lower="-2.8973" upper="2.8973" velocity="2.6100"/>
  </joint>
  <link name="left_panda_link6">
    <visual>
      <geometry>
        <mesh filename="package://robot_description/urdf/panda/meshes/visual/link6.dae"/>
      </geometry>
    </visual>
    <collision>
      <geometry>
        <mesh filename="package://robot_description/urdf/panda/meshes/collision/link6.stl"/>
      </geometry>
    </collision>
    <inertial>
      <origin rpy="0 0 0" xyz="0.06572 -0.00371 0.00153"/>
      <mass value="1.353"/>
      <inertia ixx="0.00087964522" ixy="-0.00021487814" ixz="-0.00011911662" iyy="0.00277796968" iyz="0.00001274322" izz="0.00286701969"/>
    </inertial>
  </link>
  <joint name="left_panda_joint6" type="revolute">
    <safety_controller k_position="100.0" k_velocity="40.0" soft_lower_limit="-0.0175" soft_upper_limit="3.7525"/>
    <origin rpy="1.57079632679 0 0" xyz="0 0 0"/>
    <parent link="left_panda_link5"/>
    <child link="left_panda_link6"/>
    <axis xyz="0 0 1"/>
    <limit effort="12" lower="-0.0175" upper="3.7525" velocity="2.6100"/>
  </joint>
  <link name="left_panda_link7">
    <visual>
      <geometry>
        <mesh filename="package://robot_description/urdf/panda/meshes/visual/link7.dae"/>
      </geometry>
    </visual>
    <collision>
      <geometry>
        <mesh filename="package://robot_description/urdf/panda/meshes/collision/link7.stl"/>
      </geometry>
    </collision>
    <inertial>
      <origin rpy="0 0 0" xyz="0.00089 -0.00044 0.05491"/>
      <mass value="0.35973"/>
      <inertia ixx="0.00019541063" ixy="0.00000165231" ixz="0.00000148826" iyy="0.00019210361" iyz="-0.00000131132" izz="0.00017936256"/>
    </inertial>
  </link>
  <joint name="left_panda_joint7" type="revolute">
    <safety_controller k_position="100.0" k_velocity="40.0" soft_lower_limit="-2.8973" soft_upper_limit="2.8973"/>
    <origin rpy="1.57079632679 0 0" xyz="0.088 0 0"/>
    <parent link="left_panda_link6"/>
    <child link="left_panda_link7"/>
    <axis xyz="0 0 1"/>
    <limit effort="12" lower="-2.8973" upper="2.8973" velocity="2.6100"/>
  </joint>
  <link name="left_panda_link8"/>
  <joint name="left_panda_joint8" type="fixed">
    <parent link="left_panda_link7"/>
    <child link="left_panda_link8"/>
    <origin rpy="0 0 0" xyz="0 0 0.107"/>
  </joint>
  <material name="left_black">
    <color rgba="0.196 0.196 0.196 1.0"/>
  </material>
  <material name="left_white">
    <color rgba="1.0 1.0 1.0 1.0"/>
  </material>
  <link name="left_delto_base_link">
    <inertial>
      <origin rpy="5.671320207730568e-06 0.0032948722942074404 -0.00044870150924543735" xyz="0.00045499721796859983 -2.051648304165415e-06 -0.05218562175888181"/>
      <mass value="0.370"/>
      <inertia ixx="0.0009935903471030175" ixy="0" ixz="0" iyy="0.000980251548061173" iyz="0" izz="0.0003178199035240808"/>
    </inertial>
    <visual>
      <origin rpy="5.671320207730568e-06 0.0032948722942074404 -0.00044870150924543735" xyz="0.00045499721796859983 -2.051648304165415e-06 -0.05218562175888181"/>
      <geometry>
        <mesh filename="package://robot_description/urdf/tesollo_DG3F/meshes/delto_base_link.stl"/>
      </geometry>
      <material name="left_black"/>
    </visual>
    <collision>
      <origin rpy="5.671320207730568e-06 0.0032948722942074404 -0.00044870150924543735" xyz="0.00045499721796859983 -2.051648304165415e-06 -0.05218562175888181"/>
      <geometry>
        <mesh filename="package://robot_description/urdf/tesollo_DG3F/meshes/delto_base_link.stl"/>
      </geometry>
    </collision>
  </link>
  <link name="left_delto_offset_link"/>
  <joint name="left_delto_offset_joint" type="fixed">
    <parent link="left_delto_base_link"/>
    <child link="left_delto_offset_link"/>
    <origin rpy="0 0 0" xyz="0 0 0.05"/>
  </joint>
  <link name="left_F1_01">
    <inertial>
      <origin rpy="-0.17662368646091148 -1.9303231388878572e-06 1.5707855116626381" xyz="0.0003906 3.121e-08 -0.014"/>
      <mass value="0.061"/>
      <inertia ixx="1.924000000025899e-05" ixy="0" ixz="0" iyy="1.709411627342488e-05" iyz="0" izz="5.9478837263161295e-06"/>
    </inertial>
    <visual>
      <origin rpy="-0.1443920950720977 1.9855029389503898e-05 1.5709191233325221" xyz="0.0018977016221143523 -1.0017682763976983e-06 -0.022983822146236326"/>
      <geometry>
        <mesh filename="package://robot_description/urdf/tesollo_DG3F/meshes/link_01.stl"/>
      </geometry>
      <material name="left_black"/>
    </visual>
    <collision>
      <origin rpy="-0.1443920950720977 1.9855029389503898e-05 1.5709191233325221" xyz="0.0018977016221143523 -1.0017682763976983e-06 -0.022983822146236326"/>
      <geometry>
        <mesh filename="package://robot_description/urdf/tesollo_DG3F/meshes/link_01.stl"/>
      </geometry>
    </collision>
  </link>
  <link name="left_F1_02">
    <inertial>
      <origin rpy="-0.0036890516412144943 0.31688564121750695 -0.0027736178951144786" xyz="0.01 3.444e-06 0.016"/>
      <mass value="0.025"/>
      <inertia ixx="7.164797732610912e-06" ixy="0" ixz="0" iyy="6.31301833122199e-06" iyz="0" izz="3.274183936167101e-06"/>
    </inertial>
    <visual>
      <origin rpy="-0.03118104794815292 0.3757385725887219 -0.024334342208719002" xyz="0.010322007813576017 0.000267674195662055 0.013590600703218703"/>
      <geometry>
        <mesh filename="package://robot_description/urdf/tesollo_DG3F/meshes/link_02.stl"/>
      </geometry>
      <material name="left_black"/>
    </visual>
    <collision>
      <origin rpy="-0.03118104794815292 0.3757385725887219 -0.024334342208719002" xyz="0.010322007813576017 0.000267674195662055 0.013590600703218703"/>
      <geometry>
        <mesh filename="package://robot_description/urdf/tesollo_DG3F/meshes/link_02.stl"/>
      </geometry>
    </collision>
  </link>
  <link name="left_F1_03">
    <inertial>
      <origin rpy="1.5651066808062148 -0.0008576993469346927 1.5562600280492769" xyz="0.014 -0.0004527 -3.953e-05"/>
      <mass value="0.051"/>
      <inertia ixx="1.6912201686125405e-05" ixy="0" ixz="0" iyy="1.4940271596370447e-05" iyz="0" izz="6.505526717504149e-06"/>
    </inertial>
    <visual>
      <origin rpy="1.5405533073968862 -0.0023628127138719535 1.5994547590929262" xyz="0.019034639558839914 -0.0007611783816217545 0.00015734818842133856"/>
      <geometry>
        <mesh filename="package://robot_description/urdf/tesollo_DG3F/meshes/link_03.stl"/>
      </geometry>
      <material name="left_black"/>
    </visual>
    <collision>
      <origin rpy="1.5405533073968862 -0.0023628127138719535 1.5994547590929262" xyz="0.019034639558839914 -0.0007611783816217545 0.00015734818842133856"/>
      <geometry>
        <mesh filename="package://robot_description/urdf/tesollo_DG3F/meshes/link_03.stl"/>
      </geometry>
    </collision>
  </link>
  <link name="left_F1_04">
    <inertial>
      <origin rpy="1.5668480451228681 -0.0008686188531681349 1.5829731507939977" xyz="0.012 -0.0002269 -4.676e-05"/>
      <mass value="0.058"/>
      <inertia ixx="1.0860820276783573e-05" ixy="0" ixz="0" iyy="9.902070548178027e-06" iyz="0" izz="5.330109175038405e-06"/>
    </inertial>
    <visual>
      <origin rpy="1.5745317514920234 0.003601150001683928 1.6650413701206925" xyz="0.011992289866897352 -0.0007726988011287212 -5.201111709052532e-06"/>
      <geometry>
        <mesh filename="package://robot_description/urdf/tesollo_DG3F/meshes/link_04.stl"/>
      </geometry>
      <material name="left_black"/>
    </visual>
    <collision>
      <origin rpy="1.5745317514920234 0.003601150001683928 1.6650413701206925" xyz="0.011992289866897352 -0.0007726988011287212 -5.201111709052532e-06"/>
      <geometry>
        <mesh filename="package://robot_description/urdf/tesollo_DG3F/meshes/link_04.stl"/>
      </geometry>
    </collision>
  </link>
  <link name="left_F1_TIP">
    <inertial>
      <origin rpy="1.5708008179564292 -3.695361794919805e-05 1.5210948927815267" xyz="0.045 -0.000436 -7.22e-08"/>
      <mass value="0.013"/>
      <inertia ixx="1.5965708653714455e-06" ixy="0" ixz="0" iyy="1.2999999996018677e-06" iyz="0" izz="9.60129135026688e-07"/>
    </inertial>
    <visual>
      <origin rpy="1.5708745579876908 -1.019986385419891e-05 1.5204133624130758" xyz="0.044959448417087294 -0.0004226309811080281 2.3018946871860735e-07"/>
      <geometry>
        <mesh filename="package://robot_description/urdf/tesollo_DG3F/meshes/link_tip_high.stl"/>
      </geometry>
      <material name="left_white"/>
    </visual>
    <collision>
      <origin rpy="1.5708745579876908 -1.019986385419891e-05 1.5204133624130758" xyz="0.044959448417087294 -0.0004226309811080281 2.3018946871860735e-07"/>
      <geometry>
        <mesh filename="package://robot_description/urdf/tesollo_DG3F/meshes/link_tip_high.stl"/>
      </geometry>
    </collision>
  </link>
  <link name="left_F2_01">
    <inertial>
      <origin rpy="-0.17662368646091148 -1.9303231388878572e-06 1.5707855116626381" xyz="0.0003906 3.121e-08 -0.014"/>
      <mass value="0.061"/>
      <inertia ixx="1.924000000025899e-05" ixy="0" ixz="0" iyy="1.709411627342488e-05" iyz="0" izz="5.9478837263161295e-06"/>
    </inertial>
    <visual>
      <origin rpy="-0.1443920950720977 1.9855029389503898e-05 1.5709191233325221" xyz="0.0018977016221143523 -1.0017682763976983e-06 -0.022983822146236326"/>
      <geometry>
        <mesh filename="package://robot_description/urdf/tesollo_DG3F/meshes/link_01.stl"/>
      </geometry>
      <material name="left_black"/>
    </visual>
    <collision>
      <origin rpy="-0.1443920950720977 1.9855029389503898e-05 1.5709191233325221" xyz="0.0018977016221143523 -1.0017682763976983e-06 -0.022983822146236326"/>
      <geometry>
        <mesh filename="package://robot_description/urdf/tesollo_DG3F/meshes/link_01.stl"/>
      </geometry>
    </collision>
  </link>
  <link name="left_F2_02">
    <inertial>
      <origin rpy="-0.0036890516412144943 0.31688564121750695 -0.0027736178951144786" xyz="0.01 3.444e-06 0.016"/>
      <mass value="0.025"/>
      <inertia ixx="7.164797732610912e-06" ixy="0" ixz="0" iyy="6.31301833122199e-06" iyz="0" izz="3.274183936167101e-06"/>
    </inertial>
    <visual>
      <origin rpy="-0.03118104794815292 0.3757385725887219 -0.024334342208719002" xyz="0.010322007813576017 0.000267674195662055 0.013590600703218703"/>
      <geometry>
        <mesh filename="package://robot_description/urdf/tesollo_DG3F/meshes/link_02.stl"/>
      </geometry>
      <material name="left_black"/>
    </visual>
    <collision>
      <origin rpy="-0.03118104794815292 0.3757385725887219 -0.024334342208719002" xyz="0.010322007813576017 0.000267674195662055 0.013590600703218703"/>
      <geometry>
        <mesh filename="package://robot_description/urdf/tesollo_DG3F/meshes/link_02.stl"/>
      </geometry>
    </collision>
  </link>
  <link name="left_F2_03">
    <inertial>
      <origin rpy="1.5651066808062148 -0.0008576993469346927 1.5562600280492769" xyz="0.014 -0.0004527 -3.953e-05"/>
      <mass value="0.051"/>
      <inertia ixx="1.6912201686125405e-05" ixy="0" ixz="0" iyy="1.4940271596370447e-05" iyz="0" izz="6.505526717504149e-06"/>
    </inertial>
    <visual>
      <origin rpy="1.5405533073968862 -0.0023628127138719535 1.5994547590929262" xyz="0.019034639558839914 -0.0007611783816217545 0.00015734818842133856"/>
      <geometry>
        <mesh filename="package://robot_description/urdf/tesollo_DG3F/meshes/link_03.stl"/>
      </geometry>
      <material name="left_black"/>
    </visual>
    <collision>
      <origin rpy="1.5405533073968862 -0.0023628127138719535 1.5994547590929262" xyz="0.019034639558839914 -0.0007611783816217545 0.00015734818842133856"/>
      <geometry>
        <mesh filename="package://robot_description/urdf/tesollo_DG3F/meshes/link_03.stl"/>
      </geometry>
    </collision>
  </link>
  <link name="left_F2_04">
    <inertial>
      <origin rpy="1.5668480451228681 -0.0008686188531681349 1.5829731507939977" xyz="0.012 -0.0002269 -4.676e-05"/>
      <mass value="0.058"/>
      <inertia ixx="1.0860820276783573e-05" ixy="0" ixz="0" iyy="9.902070548178027e-06" iyz="0" izz="5.330109175038405e-06"/>
    </inertial>
    <visual>
      <origin rpy="1.5745317514920234 0.003601150001683928 1.6650413701206925" xyz="0.011992289866897352 -0.0007726988011287212 -5.201111709052532e-06"/>
      <geometry>
        <mesh filename="package://robot_description/urdf/tesollo_DG3F/meshes/link_04.stl"/>
      </geometry>
      <material name="left_black"/>
    </visual>
    <collision>
      <origin rpy="1.5745317514920234 0.003601150001683928 1.6650413701206925" xyz="0.011992289866897352 -0.0007726988011287212 -5.201111709052532e-06"/>
      <geometry>
        <mesh filename="package://robot_description/urdf/tesollo_DG3F/meshes/link_04.stl"/>
      </geometry>
    </collision>
  </link>
  <link name="left_F2_TIP">
    <inertial>
      <origin rpy="1.5708008179564292 -3.695361794919805e-05 1.5210948927815267" xyz="0.045 -0.000436 -7.22e-08"/>
      <mass value="0.013"/>
      <inertia ixx="1.5965708653714455e-06" ixy="0" ixz="0" iyy="1.2999999996018677e-06" iyz="0" izz="9.60129135026688e-07"/>
    </inertial>
    <visual>
      <origin rpy="1.5708745579876908 -1.019986385419891e-05 1.5204133624130758" xyz="0.044959448417087294 -0.0004226309811080281 2.3018946871860735e-07"/>
      <geometry>
        <mesh filename="package://robot_description/urdf/tesollo_DG3F/meshes/link_tip_high.stl"/>
      </geometry>
      <material name="left_white"/>
    </visual>
    <collision>
      <origin rpy="1.5708745579876908 -1.019986385419891e-05 1.5204133624130758" xyz="0.044959448417087294 -0.0004226309811080281 2.3018946871860735e-07"/>
      <geometry>
        <mesh filename="package://robot_description/urdf/tesollo_DG3F/meshes/link_tip_high.stl"/>
      </geometry>
    </collision>
  </link>
  <link name="left_F3_01">
    <inertial>
      <origin rpy="-0.17662368646091148 -1.9303231388878572e-06 1.5707855116626381" xyz="0.0003906 3.121e-08 -0.014"/>
      <mass value="0.061"/>
      <inertia ixx="1.924000000025899e-05" ixy="0" ixz="0" iyy="1.709411627342488e-05" iyz="0" izz="5.9478837263161295e-06"/>
    </inertial>
    <visual>
      <origin rpy="-0.1443920950720977 1.9855029389503898e-05 1.5709191233325221" xyz="0.0018977016221143523 -1.0017682763976983e-06 -0.022983822146236326"/>
      <geometry>
        <mesh filename="package://robot_description/urdf/tesollo_DG3F/meshes/link_01.stl"/>
      </geometry>
      <material name="left_black"/>
    </visual>
    <collision>
      <origin rpy="-0.1443920950720977 1.9855029389503898e-05 1.5709191233325221" xyz="0.0018977016221143523 -1.0017682763976983e-06 -0.022983822146236326"/>
      <geometry>
        <mesh filename="package://robot_description/urdf/tesollo_DG3F/meshes/link_01.stl"/>
      </geometry>
    </collision>
  </link>
  <link name="left_F3_02">
    <inertial>
      <origin rpy="-0.0036890516412144943 0.31688564121750695 -0.0027736178951144786" xyz="0.01 3.444e-06 0.016"/>
      <mass value="0.025"/>
      <inertia ixx="7.164797732610912e-06" ixy="0" ixz="0" iyy="6.31301833122199e-06" iyz="0" izz="3.274183936167101e-06"/>
    </inertial>
    <visual>
      <origin rpy="-0.03118104794815292 0.3757385725887219 -0.024334342208719002" xyz="0.010322007813576017 0.000267674195662055 0.013590600703218703"/>
      <geometry>
        <mesh filename="package://robot_description/urdf/tesollo_DG3F/meshes/link_02.stl"/>
      </geometry>
      <material name="left_black"/>
    </visual>
    <collision>
      <origin rpy="-0.03118104794815292 0.3757385725887219 -0.024334342208719002" xyz="0.010322007813576017 0.000267674195662055 0.013590600703218703"/>
      <geometry>
        <mesh filename="package://robot_description/urdf/tesollo_DG3F/meshes/link_02.stl"/>
      </geometry>
    </collision>
  </link>
  <link name="left_F3_03">
    <inertial>
      <origin rpy="1.5651066808062148 -0.0008576993469346927 1.5562600280492769" xyz="0.014 -0.0004527 -3.953e-05"/>
      <mass value="0.051"/>
      <inertia ixx="1.6912201686125405e-05" ixy="0" ixz="0" iyy="1.4940271596370447e-05" iyz="0" izz="6.505526717504149e-06"/>
    </inertial>
    <visual>
      <origin rpy="1.5405533073968862 -0.0023628127138719535 1.5994547590929262" xyz="0.019034639558839914 -0.0007611783816217545 0.00015734818842133856"/>
      <geometry>
        <mesh filename="package://robot_description/urdf/tesollo_DG3F/meshes/link_03.stl"/>
      </geometry>
      <material name="left_black"/>
    </visual>
    <collision>
      <origin rpy="1.5405533073968862 -0.0023628127138719535 1.5994547590929262" xyz="0.019034639558839914 -0.0007611783816217545 0.00015734818842133856"/>
      <geometry>
        <mesh filename="package://robot_description/urdf/tesollo_DG3F/meshes/link_03.stl"/>
      </geometry>
    </collision>
  </link>
  <link name="left_F3_04">
    <inertial>
      <origin rpy="1.5668480451228681 -0.0008686188531681349 1.5829731507939977" xyz="0.012 -0.0002269 -4.676e-05"/>
      <mass value="0.058"/>
      <inertia ixx="1.0860820276783573e-05" ixy="0" ixz="0" iyy="9.902070548178027e-06" iyz="0" izz="5.330109175038405e-06"/>
    </inertial>
    <visual>
      <origin rpy="1.5745317514920234 0.003601150001683928 1.6650413701206925" xyz="0.011992289866897352 -0.0007726988011287212 -5.201111709052532e-06"/>
      <geometry>
        <mesh filename="package://robot_description/urdf/tesollo_DG3F/meshes/link_04.stl"/>
      </geometry>
      <material name="left_black"/>
    </visual>
    <collision>
      <origin rpy="1.5745317514920234 0.003601150001683928 1.6650413701206925" xyz="0.011992289866897352 -0.0007726988011287212 -5.201111709052532e-06"/>
      <geometry>
        <mesh filename="package://robot_description/urdf/tesollo_DG3F/meshes/link_04.stl"/>
      </geometry>
    </collision>
  </link>
  <link name="left_F3_TIP">
    <inertial>
      <origin rpy="1.5708008179564292 -3.695361794919805e-05 1.5210948927815267" xyz="0.045 -0.000436 -7.22e-08"/>
      <mass value="0.013"/>
      <inertia ixx="1.5965708653714455e-06" ixy="0" ixz="0" iyy="1.2999999996018677e-06" iyz="0" izz="9.60129135026688e-07"/>
    </inertial>
    <visual>
      <origin rpy="1.5708745579876908 -1.019986385419891e-05 1.5204133624130758" xyz="0.044959448417087294 -0.0004226309811080281 2.3018946871860735e-07"/>
      <geometry>
        <mesh filename="package://robot_description/urdf/tesollo_DG3F/meshes/link_tip_high.stl"/>
      </geometry>
      <material name="left_white"/>
    </visual>
    <collision>
      <origin rpy="1.5708745579876908 -1.019986385419891e-05 1.5204133624130758" xyz="0.044959448417087294 -0.0004226309811080281 2.3018946871860735e-07"/>
      <geometry>
        <mesh filename="package://robot_description/urdf/tesollo_DG3F/meshes/link_tip_high.stl"/>
      </geometry>
    </collision>
  </link>
  <!--Joint -->
  <joint name="left_F1M1" type="revolute">
    <origin rpy="0 0 0" xyz="0.0265 0.0 0.0"/>
    <parent link="left_delto_base_link"/>
    <child link="left_F1_01"/>
    <axis xyz="0.0 0.0 1.0"/>
    <limit effort="10.0" lower="-1.0472" upper="1.0472" velocity="5.0"/>
    <dynamics damping="1.1" friction="1.1"/>
  </joint>
  <joint name="left_F1M2" type="revolute">
    <origin rpy="-3.1415926207728213 -1.570796290294655 0.0" xyz="0.0 0.0 0.0"/>
    <parent link="left_F1_01"/>
    <child link="left_F1_02"/>
    <axis xyz="0.0 0.0 1.0"/>
    <limit effort="10.0" lower="-1.76278" upper="1.76278" velocity="5.0"/>
    <dynamics damping="1.1" friction="1.1"/>
  </joint>
  <joint name="left_F1M3" type="revolute">
    <origin rpy="-1.5707963295583207 -1.5707963267948966 0.0" xyz="0.02022 0.0 0.03136"/>
    <parent link="left_F1_02"/>
    <child link="left_F1_03"/>
    <axis xyz="0.0 0.0 1.0"/>
    <limit effort="10.0" lower="-0.15708" upper="2.53073" velocity="5.0"/>
    <dynamics damping="1.1" friction="1.1"/>
  </joint>
  <joint name="left_F1M4" type="revolute">
    <origin rpy="0 0 0" xyz="0.0434 0.0 0.0"/>
    <parent link="left_F1_03"/>
    <child link="left_F1_04"/>
    <axis xyz="0.0 0.0 1.0"/>
    <limit effort="10.0" lower="-0.226893" upper="2.02458" velocity="5.0"/>
    <dynamics damping="1.1" friction="1.1"/>
  </joint>
  <joint name="left_TIP1" type="fixed">
    <origin rpy="0 0 0" xyz="0.0 0.0 0.0"/>
    <parent link="left_F1_04"/>
    <child link="left_F1_TIP"/>
  </joint>
  <!-- FINGER 2-->
  <joint name="left_F2M1" type="revolute">
    <origin rpy="0 0 -3.14" xyz="-0.01334 0.023 0.0"/>
    <parent link="left_delto_base_link"/>
    <child link="left_F2_01"/>
    <axis xyz="0.0 0.0 1.0"/>
    <limit effort="10.0" lower="-1.91986" upper="0.139626" velocity="5.0"/>
    <dynamics damping="1.1" friction="1.1"/>
  </joint>
  <joint name="left_F2M2" type="revolute">
    <origin rpy="-3.14 -1.57 0" xyz="0.0 0.0 0.0"/>
    <parent link="left_F2_01"/>
    <child link="left_F2_02"/>
    <axis xyz="0.0 0.0 1.0"/>
    <limit effort="10.0" lower="-1.76278" upper="1.76278" velocity="5.0"/>
    <dynamics damping="1.1" friction="1.1"/>
  </joint>
  <joint name="left_F2M3" type="revolute">
    <origin rpy="-1.57 -1.57 0" xyz="0.02022 0.0 0.03136"/>
    <parent link="left_F2_02"/>
    <child link="left_F2_03"/>
    <axis xyz="0.0 0.0 1.0"/>
    <limit effort="10.0" lower="-0.15708" upper="2.53073" velocity="5.0"/>
    <dynamics damping="1.1" friction="1.1"/>
  </joint>
  <joint name="left_F2M4" type="revolute">
    <origin rpy="0 0 0" xyz="0.0434 0.0 0.0"/>
    <parent link="left_F2_03"/>
    <child link="left_F2_04"/>
    <axis xyz="0.0 0.0 1.0"/>
    <limit effort="10.0" lower="-0.226893" upper="2.02458" velocity="5.0"/>
    <dynamics damping="1.1" friction="1.1"/>
  </joint>
  <joint name="left_TIP2" type="fixed">
    <origin rpy="0 0 0" xyz="0.0 0.0 0.0"/>
    <parent link="left_F2_04"/>
    <child link="left_F2_TIP"/>
  </joint>
  <!-- FINGER 3-->
  <joint name="left_F3M1" type="revolute">
    <origin rpy="0 0 -3.14" xyz="-0.01334 -0.023 0.0"/>
    <parent link="left_delto_base_link"/>
    <child link="left_F3_01"/>
    <axis xyz="0.0 0.0 1.0"/>
    <limit effort="10.0" lower="-0.0872665" upper="2.00713" velocity="5.0"/>
    <dynamics damping="1.1" friction="1.1"/>
  </joint>
  <joint name="left_F3M2" type="revolute">
    <origin rpy="-3.14 -1.57 0" xyz="0.0 0.0 0.0"/>
    <parent link="left_F3_01"/>
    <child link="left_F3_02"/>
    <axis xyz="0.0 0.0 1.0"/>
    <limit effort="10.0" lower="-1.76278" upper="1.76278" velocity="5.0"/>
    <dynamics damping="1.1" friction="1.1"/>
  </joint>
  <joint name="left_F3M3" type="revolute">
    <origin rpy="-1.57 -1.57 0" xyz="0.02022 0.0 0.03136"/>
    <parent link="left_F3_02"/>
    <child link="left_F3_03"/>
    <axis xyz="0.0 0.0 1.0"/>
    <limit effort="10.0" lower="-0.15708" upper="2.53073" velocity="5.0"/>
    <dynamics damping="1.1" friction="1.1"/>
  </joint>
  <joint name="left_F3M4" type="revolute">
    <origin rpy="0 0 0" xyz="0.0434 0.0 0.0"/>
    <parent link="left_F3_03"/>
    <child link="left_F3_04"/>
    <axis xyz="0.0 0.0 1.0"/>
    <limit effort="10.0" lower="-0.226893" upper="2.02458" velocity="5.0"/>
    <dynamics damping="1.1" friction="1.1"/>
  </joint>
  <joint name="left_TIP3" type="fixed">
    <origin rpy="0 0 0" xyz="0.0 0.0 0.0"/>
    <parent link="left_F3_04"/>
    <child link="left_F3_TIP"/>
  </joint>
  <!-- Connection Joints -->
  <joint name="left_panda_gripper_joint" type="fixed">
    <parent link="left_panda_link8"/>
    <child link="left_delto_base_link"/>
    <origin rpy="0 0 -1.015" xyz="0 0 0.106"/>
  </joint>
  <link name="right_panda_link0">
    <visual>
      <geometry>
        <mesh filename="package://robot_description/urdf/panda/meshes/visual/link0.dae"/>
      </geometry>
    </visual>
    <collision>
      <geometry>
        <mesh filename="package://robot_description/urdf/panda/meshes/collision/link0.stl"/>
      </geometry>
    </collision>
    <inertial>
      <origin rpy="0 0 0" xyz="-0.0172 0.0004 0.0745"/>
      <mass value="2.3966"/>
      <inertia ixx="0.0090" ixy="0.0000" ixz="0.0020" iyy="0.0115" iyz="0.0000" izz="0.0085"/>
    </inertial>
  </link>
  <link name="right_panda_link1">
    <visual>
      <geometry>
        <mesh filename="package://robot_description/urdf/panda/meshes/visual/link1.dae"/>
      </geometry>
    </visual>
    <collision>
      <geometry>
        <mesh filename="package://robot_description/urdf/panda/meshes/collision/link1.stl"/>
      </geometry>
    </collision>
    <inertial>
      <origin rpy="0 0 0" xyz="0.00033 -0.02204 -0.04762"/>
      <mass value="2.7907"/>
      <inertia ixx="0.01564782655" ixy="0.00000531236" ixz="-0.00003676721" iyy="0.01439883526" iyz="-0.00248480843" izz="0.00500443991"/>
    </inertial>
  </link>
  <joint name="right_panda_joint1" type="revolute">
    <safety_controller k_position="100.0" k_velocity="40.0" soft_lower_limit="-2.8973" soft_upper_limit="2.8973"/>
    <origin rpy="0 0 0" xyz="0 0 0.333"/>
    <parent link="right_panda_link0"/>
    <child link="right_panda_link1"/>
    <axis xyz="0 0 1"/>
    <limit effort="87" lower="-2.8973" upper="2.8973" velocity="2.1750"/>
  </joint>
  <link name="right_panda_link2">
    <visual>
      <geometry>
        <mesh filename="package://robot_description/urdf/panda/meshes/visual/link2.dae"/>
      </geometry>
    </visual>
    <collision>
      <geometry>
        <mesh filename="package://robot_description/urdf/panda/meshes/collision/link2.stl"/>
      </geometry>
    </collision>
    <inertial>
      <origin rpy="0 0 0" xyz="0.00038 -0.09211 0.01908"/>
      <mass value="2.5420"/>
      <inertia ixx="0.01662427728" ixy="0.00003086077" ixz="0.00000835940" iyy="0.00462501261" iyz="0.00355899830" izz="0.01545124526"/>
    </inertial>
  </link>
  <joint name="right_panda_joint2" type="revolute">
    <safety_controller k_position="100.0" k_velocity="40.0" soft_lower_limit="-1.7628" soft_upper_limit="1.7628"/>
    <origin rpy="-1.57079632679 0 0" xyz="0 0 0"/>
    <parent link="right_panda_link1"/>
    <child link="right_panda_link2"/>
    <axis xyz="0 0 1"/>
    <limit effort="87" lower="-1.7628" upper="1.7628" velocity="2.1750"/>
  </joint>
  <link name="right_panda_link3">
    <visual>
      <geometry>
        <mesh filename="package://robot_description/urdf/panda/meshes/visual/link3.dae"/>
      </geometry>
    </visual>
    <collision>
      <geometry>
        <mesh filename="package://robot_description/urdf/panda/meshes/collision/link3.stl"/>
      </geometry>
    </collision>
    <inertial>
      <origin rpy="0 0 0" xyz="0.05152 0.01696 -0.02971"/>
      <mass value="2.2513"/>
      <inertia ixx="0.00631741992" ixy="0.00097309955" ixz="0.00292525834" iyy="0.00866285493" iyz="0.00093469224" izz="0.00657804051"/>
    </inertial>
  </link>
  <joint name="right_panda_joint3" type="revolute">
    <safety_controller k_position="100.0" k_velocity="40.0" soft_lower_limit="-2.8973" soft_upper_limit="2.8973"/>
    <origin rpy="1.57079632679 0 0" xyz="0 -0.316 0"/>
    <parent link="right_panda_link2"/>
    <child link="right_panda_link3"/>
    <axis xyz="0 0 1"/>
    <limit effort="87" lower="-2.8973" upper="2.8973" velocity="2.1750"/>
  </joint>
  <link name="right_panda_link4">
    <visual>
      <geometry>
        <mesh filename="package://robot_description/urdf/panda/meshes/visual/link4.dae"/>
      </geometry>
    </visual>
    <collision>
      <geometry>
        <mesh filename="package://robot_description/urdf/panda/meshes/collision/link4.stl"/>
      </geometry>
    </collision>
    <inertial>
      <origin rpy="0 0 0" xyz="-0.05113 0.05825 0.01698"/>
      <mass value="2.2037"/>
      <inertia ixx="0.00784585566" ixy="-0.00339591957" ixz="0.00158704074" iyy="0.00649543136" iyz="-0.00181477884" izz="0.01003079917"/>
    </inertial>
  </link>
  <joint name="right_panda_joint4" type="revolute">
    <safety_controller k_position="100.0" k_velocity="40.0" soft_lower_limit="-3.0718" soft_upper_limit="-0.0698"/>
    <origin rpy="1.57079632679 0 0" xyz="0.0825 0 0"/>
    <parent link="right_panda_link3"/>
    <child link="right_panda_link4"/>
    <axis xyz="0 0 1"/>
    <limit effort="87" lower="-3.0718" upper="-0.0698" velocity="2.1750"/>
  </joint>
  <link name="right_panda_link5">
    <visual>
      <geometry>
        <mesh filename="package://robot_description/urdf/panda/meshes/visual/link5.dae"/>
      </geometry>
    </visual>
    <collision>
      <geometry>
        <mesh filename="package://robot_description/urdf/panda/meshes/collision/link5.stl"/>
      </geometry>
    </collision>
    <inertial>
      <origin rpy="0 0 0" xyz="-0.00005 0.03730 -0.09280"/>
      <mass value="2.2855"/>
      <inertia ixx="0.02297014781" ixy="-0.00000949345" ixz="-0.00002063156" iyy="0.02095060919" iyz="0.00382345782" izz="0.00430606551"/>
    </inertial>
  </link>
  <joint name="right_panda_joint5" type="revolute">
    <safety_controller k_position="100.0" k_velocity="40.0" soft_lower_limit="-2.8973" soft_upper_limit="2.8973"/>
    <origin rpy="-1.57079632679 0 0" xyz="-0.0825 0.384 0"/>
    <parent link="right_panda_link4"/>
    <child link="right_panda_link5"/>
    <axis xyz="0 0 1"/>
    <limit effort="12" lower="-2.8973" upper="2.8973" velocity="2.6100"/>
  </joint>
  <link name="right_panda_link6">
    <visual>
      <geometry>
        <mesh filename="package://robot_description/urdf/panda/meshes/visual/link6.dae"/>
      </geometry>
    </visual>
    <collision>
      <geometry>
        <mesh filename="package://robot_description/urdf/panda/meshes/collision/link6.stl"/>
      </geometry>
    </collision>
    <inertial>
      <origin rpy="0 0 0" xyz="0.06572 -0.00371 0.00153"/>
      <mass value="1.353"/>
      <inertia ixx="0.00087964522" ixy="-0.00021487814" ixz="-0.00011911662" iyy="0.00277796968" iyz="0.00001274322" izz="0.00286701969"/>
    </inertial>
  </link>
  <joint name="right_panda_joint6" type="revolute">
    <safety_controller k_position="100.0" k_velocity="40.0" soft_lower_limit="-0.0175" soft_upper_limit="3.7525"/>
    <origin rpy="1.57079632679 0 0" xyz="0 0 0"/>
    <parent link="right_panda_link5"/>
    <child link="right_panda_link6"/>
    <axis xyz="0 0 1"/>
    <limit effort="12" lower="-0.0175" upper="3.7525" velocity="2.6100"/>
  </joint>
  <link name="right_panda_link7">
    <visual>
      <geometry>
        <mesh filename="package://robot_description/urdf/panda/meshes/visual/link7.dae"/>
      </geometry>
    </visual>
    <collision>
      <geometry>
        <mesh filename="package://robot_description/urdf/panda/meshes/collision/link7.stl"/>
      </geometry>
    </collision>
    <inertial>
      <origin rpy="0 0 0" xyz="0.00089 -0.00044 0.05491"/>
      <mass value="0.35973"/>
      <inertia ixx="0.00019541063" ixy="0.00000165231" ixz="0.00000148826" iyy="0.00019210361" iyz="-0.00000131132" izz="0.00017936256"/>
    </inertial>
  </link>
  <joint name="right_panda_joint7" type="revolute">
    <safety_controller k_position="100.0" k_velocity="40.0" soft_lower_limit="-2.8973" soft_upper_limit="2.8973"/>
    <origin rpy="1.57079632679 0 0" xyz="0.088 0 0"/>
    <parent link="right_panda_link6"/>
    <child link="right_panda_link7"/>
    <axis xyz="0 0 1"/>
    <limit effort="12" lower="-2.8973" upper="2.8973" velocity="2.6100"/>
  </joint>
  <link name="right_panda_link8"/>
  <joint name="right_panda_joint8" type="fixed">
    <parent link="right_panda_link7"/>
    <child link="right_panda_link8"/>
    <origin rpy="0 0 0" xyz="0 0 0.107"/>
  </joint>
  <material name="right_black">
    <color rgba="0.196 0.196 0.196 1.0"/>
  </material>
  <material name="right_white">
    <color rgba="1.0 1.0 1.0 1.0"/>
  </material>
  <link name="right_delto_base_link">
    <inertial>
      <origin rpy="5.671320207730568e-06 0.0032948722942074404 -0.00044870150924543735" xyz="0.00045499721796859983 -2.051648304165415e-06 -0.05218562175888181"/>
      <mass value="0.370"/>
      <inertia ixx="0.0009935903471030175" ixy="0" ixz="0" iyy="0.000980251548061173" iyz="0" izz="0.0003178199035240808"/>
    </inertial>
    <visual>
      <origin rpy="5.671320207730568e-06 0.0032948722942074404 -0.00044870150924543735" xyz="0.00045499721796859983 -2.051648304165415e-06 -0.05218562175888181"/>
      <geometry>
        <mesh filename="package://robot_description/urdf/tesollo_DG3F/meshes/delto_base_link.stl"/>
      </geometry>
      <material name="right_black"/>
    </visual>
    <collision>
      <origin rpy="5.671320207730568e-06 0.0032948722942074404 -0.00044870150924543735" xyz="0.00045499721796859983 -2.051648304165415e-06 -0.05218562175888181"/>
      <geometry>
        <mesh filename="package://robot_description/urdf/tesollo_DG3F/meshes/delto_base_link.stl"/>
      </geometry>
    </collision>
  </link>
  <link name="right_delto_offset_link"/>
  <joint name="right_delto_offset_joint" type="fixed">
    <parent link="right_delto_base_link"/>
    <child link="right_delto_offset_link"/>
    <origin rpy="0 0 0" xyz="0 0 0.05"/>
  </joint>
  <link name="right_F1_01">
    <inertial>
      <origin rpy="-0.17662368646091148 -1.9303231388878572e-06 1.5707855116626381" xyz="0.0003906 3.121e-08 -0.014"/>
      <mass value="0.061"/>
      <inertia ixx="1.924000000025899e-05" ixy="0" ixz="0" iyy="1.709411627342488e-05" iyz="0" izz="5.9478837263161295e-06"/>
    </inertial>
    <visual>
      <origin rpy="-0.1443920950720977 1.9855029389503898e-05 1.5709191233325221" xyz="0.0018977016221143523 -1.0017682763976983e-06 -0.022983822146236326"/>
      <geometry>
        <mesh filename="package://robot_description/urdf/tesollo_DG3F/meshes/link_01.stl"/>
      </geometry>
      <material name="right_black"/>
    </visual>
    <collision>
      <origin rpy="-0.1443920950720977 1.9855029389503898e-05 1.5709191233325221" xyz="0.0018977016221143523 -1.0017682763976983e-06 -0.022983822146236326"/>
      <geometry>
        <mesh filename="package://robot_description/urdf/tesollo_DG3F/meshes/link_01.stl"/>
      </geometry>
    </collision>
  </link>
  <link name="right_F1_02">
    <inertial>
      <origin rpy="-0.0036890516412144943 0.31688564121750695 -0.0027736178951144786" xyz="0.01 3.444e-06 0.016"/>
      <mass value="0.025"/>
      <inertia ixx="7.164797732610912e-06" ixy="0" ixz="0" iyy="6.31301833122199e-06" iyz="0" izz="3.274183936167101e-06"/>
    </inertial>
    <visual>
      <origin rpy="-0.03118104794815292 0.3757385725887219 -0.024334342208719002" xyz="0.010322007813576017 0.000267674195662055 0.013590600703218703"/>
      <geometry>
        <mesh filename="package://robot_description/urdf/tesollo_DG3F/meshes/link_02.stl"/>
      </geometry>
      <material name="right_black"/>
    </visual>
    <collision>
      <origin rpy="-0.03118104794815292 0.3757385725887219 -0.024334342208719002" xyz="0.010322007813576017 0.000267674195662055 0.013590600703218703"/>
      <geometry>
        <mesh filename="package://robot_description/urdf/tesollo_DG3F/meshes/link_02.stl"/>
      </geometry>
    </collision>
  </link>
  <link name="right_F1_03">
    <inertial>
      <origin rpy="1.5651066808062148 -0.0008576993469346927 1.5562600280492769" xyz="0.014 -0.0004527 -3.953e-05"/>
      <mass value="0.051"/>
      <inertia ixx="1.6912201686125405e-05" ixy="0" ixz="0" iyy="1.4940271596370447e-05" iyz="0" izz="6.505526717504149e-06"/>
    </inertial>
    <visual>
      <origin rpy="1.5405533073968862 -0.0023628127138719535 1.5994547590929262" xyz="0.019034639558839914 -0.0007611783816217545 0.00015734818842133856"/>
      <geometry>
        <mesh filename="package://robot_description/urdf/tesollo_DG3F/meshes/link_03.stl"/>
      </geometry>
      <material name="right_black"/>
    </visual>
    <collision>
      <origin rpy="1.5405533073968862 -0.0023628127138719535 1.5994547590929262" xyz="0.019034639558839914 -0.0007611783816217545 0.00015734818842133856"/>
      <geometry>
        <mesh filename="package://robot_description/urdf/tesollo_DG3F/meshes/link_03.stl"/>
      </geometry>
    </collision>
  </link>
  <link name="right_F1_04">
    <inertial>
      <origin rpy="1.5668480451228681 -0.0008686188531681349 1.5829731507939977" xyz="0.012 -0.0002269 -4.676e-05"/>
      <mass value="0.058"/>
      <inertia ixx="1.0860820276783573e-05" ixy="0" ixz="0" iyy="9.902070548178027e-06" iyz="0" izz="5.330109175038405e-06"/>
    </inertial>
    <visual>
      <origin rpy="1.5745317514920234 0.003601150001683928 1.6650413701206925" xyz="0.011992289866897352 -0.0007726988011287212 -5.201111709052532e-06"/>
      <geometry>
        <mesh filename="package://robot_description/urdf/tesollo_DG3F/meshes/link_04.stl"/>
      </geometry>
      <material name="right_black"/>
    </visual>
    <collision>
      <origin rpy="1.5745317514920234 0.003601150001683928 1.6650413701206925" xyz="0.011992289866897352 -0.0007726988011287212 -5.201111709052532e-06"/>
      <geometry>
        <mesh filename="package://robot_description/urdf/tesollo_DG3F/meshes/link_04.stl"/>
      </geometry>
    </collision>
  </link>
  <link name="right_F1_TIP">
    <inertial>
      <origin rpy="1.5708008179564292 -3.695361794919805e-05 1.5210948927815267" xyz="0.045 -0.000436 -7.22e-08"/>
      <mass value="0.013"/>
      <inertia ixx="1.5965708653714455e-06" ixy="0" ixz="0" iyy="1.2999999996018677e-06" iyz="0" izz="9.60129135026688e-07"/>
    </inertial>
    <visual>
      <origin rpy="1.5708745579876908 -1.019986385419891e-05 1.5204133624130758" xyz="0.044959448417087294 -0.0004226309811080281 2.3018946871860735e-07"/>
      <geometry>
        <mesh filename="package://robot_description/urdf/tesollo_DG3F/meshes/link_tip_high.stl"/>
      </geometry>
      <material name="right_white"/>
    </visual>
    <collision>
      <origin rpy="1.5708745579876908 -1.019986385419891e-05 1.5204133624130758" xyz="0.044959448417087294 -0.0004226309811080281 2.3018946871860735e-07"/>
      <geometry>
        <mesh filename="package://robot_description/urdf/tesollo_DG3F/meshes/link_tip_high.stl"/>
      </geometry>
    </collision>
  </link>
  <link name="right_F2_01">
    <inertial>
      <origin rpy="-0.17662368646091148 -1.9303231388878572e-06 1.5707855116626381" xyz="0.0003906 3.121e-08 -0.014"/>
      <mass value="0.061"/>
      <inertia ixx="1.924000000025899e-05" ixy="0" ixz="0" iyy="1.709411627342488e-05" iyz="0" izz="5.9478837263161295e-06"/>
    </inertial>
    <visual>
      <origin rpy="-0.1443920950720977 1.9855029389503898e-05 1.5709191233325221" xyz="0.0018977016221143523 -1.0017682763976983e-06 -0.022983822146236326"/>
      <geometry>
        <mesh filename="package://robot_description/urdf/tesollo_DG3F/meshes/link_01.stl"/>
      </geometry>
      <material name="right_black"/>
    </visual>
    <collision>
      <origin rpy="-0.1443920950720977 1.9855029389503898e-05 1.5709191233325221" xyz="0.0018977016221143523 -1.0017682763976983e-06 -0.022983822146236326"/>
      <geometry>
        <mesh filename="package://robot_description/urdf/tesollo_DG3F/meshes/link_01.stl"/>
      </geometry>
    </collision>
  </link>
  <link name="right_F2_02">
    <inertial>
      <origin rpy="-0.0036890516412144943 0.31688564121750695 -0.0027736178951144786" xyz="0.01 3.444e-06 0.016"/>
      <mass value="0.025"/>
      <inertia ixx="7.164797732610912e-06" ixy="0" ixz="0" iyy="6.31301833122199e-06" iyz="0" izz="3.274183936167101e-06"/>
    </inertial>
    <visual>
      <origin rpy="-0.03118104794815292 0.3757385725887219 -0.024334342208719002" xyz="0.010322007813576017 0.000267674195662055 0.013590600703218703"/>
      <geometry>
        <mesh filename="package://robot_description/urdf/tesollo_DG3F/meshes/link_02.stl"/>
      </geometry>
      <material name="right_black"/>
    </visual>
    <collision>
      <origin rpy="-0.03118104794815292 0.3757385725887219 -0.024334342208719002" xyz="0.010322007813576017 0.000267674195662055 0.013590600703218703"/>
      <geometry>
        <mesh filename="package://robot_description/urdf/tesollo_DG3F/meshes/link_02.stl"/>
      </geometry>
    </collision>
  </link>
  <link name="right_F2_03">
    <inertial>
      <origin rpy="1.5651066808062148 -0.0008576993469346927 1.5562600280492769" xyz="0.014 -0.0004527 -3.953e-05"/>
      <mass value="0.051"/>
      <inertia ixx="1.6912201686125405e-05" ixy="0" ixz="0" iyy="1.4940271596370447e-05" iyz="0" izz="6.505526717504149e-06"/>
    </inertial>
    <visual>
      <origin rpy="1.5405533073968862 -0.0023628127138719535 1.5994547590929262" xyz="0.019034639558839914 -0.0007611783816217545 0.00015734818842133856"/>
      <geometry>
        <mesh filename="package://robot_description/urdf/tesollo_DG3F/meshes/link_03.stl"/>
      </geometry>
      <material name="right_black"/>
    </visual>
    <collision>
      <origin rpy="1.5405533073968862 -0.0023628127138719535 1.5994547590929262" xyz="0.019034639558839914 -0.0007611783816217545 0.00015734818842133856"/>
      <geometry>
        <mesh filename="package://robot_description/urdf/tesollo_DG3F/meshes/link_03.stl"/>
      </geometry>
    </collision>
  </link>
  <link name="right_F2_04">
    <inertial>
      <origin rpy="1.5668480451228681 -0.0008686188531681349 1.5829731507939977" xyz="0.012 -0.0002269 -4.676e-05"/>
      <mass value="0.058"/>
      <inertia ixx="1.0860820276783573e-05" ixy="0" ixz="0" iyy="9.902070548178027e-06" iyz="0" izz="5.330109175038405e-06"/>
    </inertial>
    <visual>
      <origin rpy="1.5745317514920234 0.003601150001683928 1.6650413701206925" xyz="0.011992289866897352 -0.0007726988011287212 -5.201111709052532e-06"/>
      <geometry>
        <mesh filename="package://robot_description/urdf/tesollo_DG3F/meshes/link_04.stl"/>
      </geometry>
      <material name="right_black"/>
    </visual>
    <collision>
      <origin rpy="1.5745317514920234 0.003601150001683928 1.6650413701206925" xyz="0.011992289866897352 -0.0007726988011287212 -5.201111709052532e-06"/>
      <geometry>
        <mesh filename="package://robot_description/urdf/tesollo_DG3F/meshes/link_04.stl"/>
      </geometry>
    </collision>
  </link>
  <link name="right_F2_TIP">
    <inertial>
      <origin rpy="1.5708008179564292 -3.695361794919805e-05 1.5210948927815267" xyz="0.045 -0.000436 -7.22e-08"/>
      <mass value="0.013"/>
      <inertia ixx="1.5965708653714455e-06" ixy="0" ixz="0" iyy="1.2999999996018677e-06" iyz="0" izz="9.60129135026688e-07"/>
    </inertial>
    <visual>
      <origin rpy="1.5708745579876908 -1.019986385419891e-05 1.5204133624130758" xyz="0.044959448417087294 -0.0004226309811080281 2.3018946871860735e-07"/>
      <geometry>
        <mesh filename="package://robot_description/urdf/tesollo_DG3F/meshes/link_tip_high.stl"/>
      </geometry>
      <material name="right_white"/>
    </visual>
    <collision>
      <origin rpy="1.5708745579876908 -1.019986385419891e-05 1.5204133624130758" xyz="0.044959448417087294 -0.0004226309811080281 2.3018946871860735e-07"/>
      <geometry>
        <mesh filename="package://robot_description/urdf/tesollo_DG3F/meshes/link_tip_high.stl"/>
      </geometry>
    </collision>
  </link>
  <link name="right_F3_01">
    <inertial>
      <origin rpy="-0.17662368646091148 -1.9303231388878572e-06 1.5707855116626381" xyz="0.0003906 3.121e-08 -0.014"/>
      <mass value="0.061"/>
      <inertia ixx="1.924000000025899e-05" ixy="0" ixz="0" iyy="1.709411627342488e-05" iyz="0" izz="5.9478837263161295e-06"/>
    </inertial>
    <visual>
      <origin rpy="-0.1443920950720977 1.9855029389503898e-05 1.5709191233325221" xyz="0.0018977016221143523 -1.0017682763976983e-06 -0.022983822146236326"/>
      <geometry>
        <mesh filename="package://robot_description/urdf/tesollo_DG3F/meshes/link_01.stl"/>
      </geometry>
      <material name="right_black"/>
    </visual>
    <collision>
      <origin rpy="-0.1443920950720977 1.9855029389503898e-05 1.5709191233325221" xyz="0.0018977016221143523 -1.0017682763976983e-06 -0.022983822146236326"/>
      <geometry>
        <mesh filename="package://robot_description/urdf/tesollo_DG3F/meshes/link_01.stl"/>
      </geometry>
    </collision>
  </link>
  <link name="right_F3_02">
    <inertial>
      <origin rpy="-0.0036890516412144943 0.31688564121750695 -0.0027736178951144786" xyz="0.01 3.444e-06 0.016"/>
      <mass value="0.025"/>
      <inertia ixx="7.164797732610912e-06" ixy="0" ixz="0" iyy="6.31301833122199e-06" iyz="0" izz="3.274183936167101e-06"/>
    </inertial>
    <visual>
      <origin rpy="-0.03118104794815292 0.3757385725887219 -0.024334342208719002" xyz="0.010322007813576017 0.000267674195662055 0.013590600703218703"/>
      <geometry>
        <mesh filename="package://robot_description/urdf/tesollo_DG3F/meshes/link_02.stl"/>
      </geometry>
      <material name="right_black"/>
    </visual>
    <collision>
      <origin rpy="-0.03118104794815292 0.3757385725887219 -0.024334342208719002" xyz="0.010322007813576017 0.000267674195662055 0.013590600703218703"/>
      <geometry>
        <mesh filename="package://robot_description/urdf/tesollo_DG3F/meshes/link_02.stl"/>
      </geometry>
    </collision>
  </link>
  <link name="right_F3_03">
    <inertial>
      <origin rpy="1.5651066808062148 -0.0008576993469346927 1.5562600280492769" xyz="0.014 -0.0004527 -3.953e-05"/>
      <mass value="0.051"/>
      <inertia ixx="1.6912201686125405e-05" ixy="0" ixz="0" iyy="1.4940271596370447e-05" iyz="0" izz="6.505526717504149e-06"/>
    </inertial>
    <visual>
      <origin rpy="1.5405533073968862 -0.0023628127138719535 1.5994547590929262" xyz="0.019034639558839914 -0.0007611783816217545 0.00015734818842133856"/>
      <geometry>
        <mesh filename="package://robot_description/urdf/tesollo_DG3F/meshes/link_03.stl"/>
      </geometry>
      <material name="right_black"/>
    </visual>
    <collision>
      <origin rpy="1.5405533073968862 -0.0023628127138719535 1.5994547590929262" xyz="0.019034639558839914 -0.0007611783816217545 0.00015734818842133856"/>
      <geometry>
        <mesh filename="package://robot_description/urdf/tesollo_DG3F/meshes/link_03.stl"/>
      </geometry>
    </collision>
  </link>
  <link name="right_F3_04">
    <inertial>
      <origin rpy="1.5668480451228681 -0.0008686188531681349 1.5829731507939977" xyz="0.012 -0.0002269 -4.676e-05"/>
      <mass value="0.058"/>
      <inertia ixx="1.0860820276783573e-05" ixy="0" ixz="0" iyy="9.902070548178027e-06" iyz="0" izz="5.330109175038405e-06"/>
    </inertial>
    <visual>
      <origin rpy="1.5745317514920234 0.003601150001683928 1.6650413701206925" xyz="0.011992289866897352 -0.0007726988011287212 -5.201111709052532e-06"/>
      <geometry>
        <mesh filename="package://robot_description/urdf/tesollo_DG3F/meshes/link_04.stl"/>
      </geometry>
      <material name="right_black"/>
    </visual>
    <collision>
      <origin rpy="1.5745317514920234 0.003601150001683928 1.6650413701206925" xyz="0.011992289866897352 -0.0007726988011287212 -5.201111709052532e-06"/>
      <geometry>
        <mesh filename="package://robot_description/urdf/tesollo_DG3F/meshes/link_04.stl"/>
      </geometry>
    </collision>
  </link>
  <link name="right_F3_TIP">
    <inertial>
      <origin rpy="1.5708008179564292 -3.695361794919805e-05 1.5210948927815267" xyz="0.045 -0.000436 -7.22e-08"/>
      <mass value="0.013"/>
      <inertia ixx="1.5965708653714455e-06" ixy="0" ixz="0" iyy="1.2999999996018677e-06" iyz="0" izz="9.60129135026688e-07"/>
    </inertial>
    <visual>
      <origin rpy="1.5708745579876908 -1.019986385419891e-05 1.5204133624130758" xyz="0.044959448417087294 -0.0004226309811080281 2.3018946871860735e-07"/>
      <geometry>
        <mesh filename="package://robot_description/urdf/tesollo_DG3F/meshes/link_tip_high.stl"/>
      </geometry>
      <material name="right_white"/>
    </visual>
    <collision>
      <origin rpy="1.5708745579876908 -1.019986385419891e-05 1.5204133624130758" xyz="0.044959448417087294 -0.0004226309811080281 2.3018946871860735e-07"/>
      <geometry>
        <mesh filename="package://robot_description/urdf/tesollo_DG3F/meshes/link_tip_high.stl"/>
      </geometry>
    </collision>
  </link>
  <!--Joint -->
  <joint name="right_F1M1" type="revolute">
    <origin rpy="0 0 0" xyz="0.0265 0.0 0.0"/>
    <parent link="right_delto_base_link"/>
    <child link="right_F1_01"/>
    <axis xyz="0.0 0.0 1.0"/>
    <limit effort="10.0" lower="-1.0472" upper="1.0472" velocity="5.0"/>
    <dynamics damping="1.1" friction="1.1"/>
  </joint>
  <joint name="right_F1M2" type="revolute">
    <origin rpy="-3.1415926207728213 -1.570796290294655 0.0" xyz="0.0 0.0 0.0"/>
    <parent link="right_F1_01"/>
    <child link="right_F1_02"/>
    <axis xyz="0.0 0.0 1.0"/>
    <limit effort="10.0" lower="-1.76278" upper="1.76278" velocity="5.0"/>
    <dynamics damping="1.1" friction="1.1"/>
  </joint>
  <joint name="right_F1M3" type="revolute">
    <origin rpy="-1.5707963295583207 -1.5707963267948966 0.0" xyz="0.02022 0.0 0.03136"/>
    <parent link="right_F1_02"/>
    <child link="right_F1_03"/>
    <axis xyz="0.0 0.0 1.0"/>
    <limit effort="10.0" lower="-0.15708" upper="2.53073" velocity="5.0"/>
    <dynamics damping="1.1" friction="1.1"/>
  </joint>
  <joint name="right_F1M4" type="revolute">
    <origin rpy="0 0 0" xyz="0.0434 0.0 0.0"/>
    <parent link="right_F1_03"/>
    <child link="right_F1_04"/>
    <axis xyz="0.0 0.0 1.0"/>
    <limit effort="10.0" lower="-0.226893" upper="2.02458" velocity="5.0"/>
    <dynamics damping="1.1" friction="1.1"/>
  </joint>
  <joint name="right_TIP1" type="fixed">
    <origin rpy="0 0 0" xyz="0.0 0.0 0.0"/>
    <parent link="right_F1_04"/>
    <child link="right_F1_TIP"/>
  </joint>
  <!-- FINGER 2-->
  <joint name="right_F2M1" type="revolute">
    <origin rpy="0 0 -3.14" xyz="-0.01334 0.023 0.0"/>
    <parent link="right_delto_base_link"/>
    <child link="right_F2_01"/>
    <axis xyz="0.0 0.0 1.0"/>
    <limit effort="10.0" lower="-1.91986" upper="0.139626" velocity="5.0"/>
    <dynamics damping="1.1" friction="1.1"/>
  </joint>
  <joint name="right_F2M2" type="revolute">
    <origin rpy="-3.14 -1.57 0" xyz="0.0 0.0 0.0"/>
    <parent link="right_F2_01"/>
    <child link="right_F2_02"/>
    <axis xyz="0.0 0.0 1.0"/>
    <limit effort="10.0" lower="-1.76278" upper="1.76278" velocity="5.0"/>
    <dynamics damping="1.1" friction="1.1"/>
  </joint>
  <joint name="right_F2M3" type="revolute">
    <origin rpy="-1.57 -1.57 0" xyz="0.02022 0.0 0.03136"/>
    <parent link="right_F2_02"/>
    <child link="right_F2_03"/>
    <axis xyz="0.0 0.0 1.0"/>
    <limit effort="10.0" lower="-0.15708" upper="2.53073" velocity="5.0"/>
    <dynamics damping="1.1" friction="1.1"/>
  </joint>
  <joint name="right_F2M4" type="revolute">
    <origin rpy="0 0 0" xyz="0.0434 0.0 0.0"/>
    <parent link="right_F2_03"/>
    <child link="right_F2_04"/>
    <axis xyz="0.0 0.0 1.0"/>
    <limit effort="10.0" lower="-0.226893" upper="2.02458" velocity="5.0"/>
    <dynamics damping="1.1" friction="1.1"/>
  </joint>
  <joint name="right_TIP2" type="fixed">
    <origin rpy="0 0 0" xyz="0.0 0.0 0.0"/>
    <parent link="right_F2_04"/>
    <child link="right_F2_TIP"/>
  </joint>
  <!-- FINGER 3-->
  <joint name="right_F3M1" type="revolute">
    <origin rpy="0 0 -3.14" xyz="-0.01334 -0.023 0.0"/>
    <parent link="right_delto_base_link"/>
    <child link="right_F3_01"/>
    <axis xyz="0.0 0.0 1.0"/>
    <limit effort="10.0" lower="-0.0872665" upper="2.00713" velocity="5.0"/>
    <dynamics damping="1.1" friction="1.1"/>
  </joint>
  <joint name="right_F3M2" type="revolute">
    <origin rpy="-3.14 -1.57 0" xyz="0.0 0.0 0.0"/>
    <parent link="right_F3_01"/>
    <child link="right_F3_02"/>
    <axis xyz="0.0 0.0 1.0"/>
    <limit effort="10.0" lower="-1.76278" upper="1.76278" velocity="5.0"/>
    <dynamics damping="1.1" friction="1.1"/>
  </joint>
  <joint name="right_F3M3" type="revolute">
    <origin rpy="-1.57 -1.57 0" xyz="0.02022 0.0 0.03136"/>
    <parent link="right_F3_02"/>
    <child link="right_F3_03"/>
    <axis xyz="0.0 0.0 1.0"/>
    <limit effort="10.0" lower="-0.15708" upper="2.53073" velocity="5.0"/>
    <dynamics damping="1.1" friction="1.1"/>
  </joint>
  <joint name="right_F3M4" type="revolute">
    <origin rpy="0 0 0" xyz="0.0434 0.0 0.0"/>
    <parent link="right_F3_03"/>
    <child link="right_F3_04"/>
    <axis xyz="0.0 0.0 1.0"/>
    <limit effort="10.0" lower="-0.226893" upper="2.02458" velocity="5.0"/>
    <dynamics damping="1.1" friction="1.1"/>
  </joint>
  <joint name="right_TIP3" type="fixed">
    <origin rpy="0 0 0" xyz="0.0 0.0 0.0"/>
    <parent link="right_F3_04"/>
    <child link="right_F3_TIP"/>
  </joint>
  <!-- Connection Joints -->
  <joint name="right_panda_gripper_joint" type="fixed">
    <parent link="right_panda_link8"/>
    <child link="right_delto_base_link"/>
    <origin rpy="0 0 -1.015" xyz="0 0 0.106"/>
  </joint>
  <!-- Connection Joints -->
  <joint name="left_panda_mount" type="fixed">
    <parent link="table_top"/>
    <child link="left_panda_link0"/>
    <origin rpy="0 0 0" xyz="-0.558 -0.092 0.0225"/>
  </joint>
  <joint name="right_panda_mount" type="fixed">
    <parent link="table_top"/>
    <child link="right_panda_link0"/>
    <origin rpy="0 0 3.14" xyz="0.5588 -0.092 0.0225"/>
  </joint>
  <!-- TABLE -->
  <link name="table"/>
  <link name="table_top">
    <visual>
      <origin rpy="0 0 0" xyz="0 0 0"/>
      <geometry>
        <box size="1.8288 0.62865 0.045"/>
      </geometry>
      <material name="wood">
        <color rgba="0.70 0.50 0.30 1.0"/>
      </material>
    </visual>
    <collision>
      <origin rpy="0 0 0" xyz="0 0 0"/>
      <geometry>
        <box size="1.8288 0.62865 0.045"/>
      </geometry>
    </collision>
  </link>
  <joint name="table_top_link" type="fixed">
    <parent link="table"/>
    <child link="table_top"/>
    <origin rpy="0 0 0" xyz="0 0 0.9144"/>
  </joint>
</robot>
